Workbook

Sheet Sexo_VF
A1: Accesion | B1: Muestra 1 | C1: Muestra 2 | D1: Muestra 3 | E1: Muestra 4 | F1: Muestra 5 | G1: Muestra 6 | H1: Muestra 7 | I1: Muestra 8
A2: P49822 | B2: 27.08 | C2: 7.35 | D2: 8.43 | E2: 8.43 | F2: 12.56 | G2: 14.31 | H2: 11.02 | I2: 6.4
A3: A0A8I3NCQ4 | B3: 0.53 | C3: 0.07 | D3: 0.03 | E3: 0.03 | F3: 0.15 | G3: 0.1 | H3: 0.1 | I3: 0.29
A4: A0A8I3MSG4 | B4: 8.48 | C4: 5.22 | D4: 2.08 | E4: 5.22 | F4: 4.4 | G4: 4.4 | H4: 3.69 | I4: 3.69
A5: A0A8I3N262 | B5: 1.58 | C5: 0.69 | D5: 0.79 | E5: 0.3 | F5: 1.035 | G5: 1.09 | H5: 0.98 | I5: 1.035
A6: A0A8I3NVK3 | B6: 1.53 | C6: 0.7 | D6: 1.21 | E6: 0.7 | F6: 0.94 | G6: 0.7 | H6: 1.21 | I6: 0.7
A7: A0A8I3P684 | B7: 2.75 | C7: 0.25 | D7: 0.74 | E7: 0.74 | F7: 0.74 | G7: 0.74 | H7: 0.25 | I7: 0.74
A8: A0A8I3Q3K3 | B8: 1.59 | C8: 2.87 | D8: 0.92 | E8: 0.83 | F8: 0.74 | G8: 1.47 | H8: 1.35 | I8: 1.59
A9: A0A1K0GGH0 | B9: 27.82 | C9: 9.25 | D9: 9.25 | E9: 134.97 | F9: 1.81 | G9: 12.27 | H9: 27.82 | I9: 12.27
A10: A0A8I3NFJ3 | B10: 1.4 | C10: 0.89 | D10: 0.75 | E10: 0.89 | F10: 0.89 | G10: 1.05 | H10: 0.75 | I10: 0.61
A11: A0A8I3NL87 | B11: 0.96 | C11: 0.35 | D11: 0.69 | E11: 0.45 | F11: 0.82 | G11: 0.25 | H11: 0.35 | I11: 0.82
A12: A0A8I3P0H1 | B12: 0.27 | C12: 0.17 | D12: 0.05 | E12: 0.08 | F12: 0.155 | G12: 0.11 | H12: 0.155 | I12: 0.2
A13: A0A8I3PB96 | B13: 3.32 | C13: 7.97 | D13: 5.23 | E13: 5.23 | F13: 7.97 | G13: 7.97 | H13: 7.97 | I13: 11.94
... A70: Q50KA9 | B70: 1.07 | C70: 1.07 | D70: 1.07 | E70: 1.07 | F70: 1.64 | G70: 1.64 | H70: 1.64 | I70: 1.64
A71: Q29393 | B71: 0.7 | C71: =MEDIAN(B71,D71) -> 0.535 | D71: 0.37 | E71: 0.535 | F71: 1.1 | G71: 1.1 | H71: 1.1 | I71: 1.1
A72: P60529 | B72: 14.35 | C72: 14.35 | D72: 14.35 | E72: 14.35 | F72: 10.68 | G72: 10.68 | H72: 10.68 | I72: 10.68
A73: P33703 | B73: 0.71 | C73: 0.71 | D73: 0.71 | E73: 0.71 | F73: =MEDIAN(G73,I73) -> 0.31 | G73: 0.38 | H73: 0.31 | I73: 0.24
A74: E2RE76 | B74: 0.49 | C74: =MEDIAN(B74,E74) -> 0.355 | D74: 0.355 | E74: 0.22 | F74: 0.49 | G74: 0.49 | H74: 0.49 | I74: 0.49
A75: E2R6K5 | B75: 0.72 | C75: 0.72 | D75: 0.72 | E75: 0.72 | F75: 1.96 | G75: 1.96 | H75: 1.96 | I75: 1.96
A76: A0A8I3S396 | B76: 0.28 | C76: 0.28 | D76: 0.28 | E76: 0.28 | F76: 0.44 | G76: 0.44 | H76: 0.44 | I76: 0.44
A77: A0A8I3S2Z8 | B77: 0.2 | C77: 0.2 | D77: 0.2 | E77: 0.2 | F77: 0.2 | G77: =MEDIAN(F77,I77) -> 0.26 | H77: 0.26 | I77: 0.32
A78: A0A8I3S0B7 | B78: 0.32 | C78: 0.32 | D78: 0.32 | E78: 0.32 | F78: 0.2 | G78: 0.2 | H78: 0.2 | I78: 0.2
A79: A0A8I3RZV0 | B79: 0.28 | C79: 0.28 | D79: 0.28 | E79: 0.28 | F79: 1.49 | G79: 1.49 | H79: 1.49 | I79: 1.49
A80: A0A8I3RR88 | B80: 0.18 | C80: 0.18 | D80: 0.18 | E80: 0.18 | F80: 0.27 | G80: 0.18 | H80: =MEDIAN(F80:G80) -> 0.225 | I80: 0.225
A81: A0A8I3Q5N9 | B81: 0.27 | C81: 0.27 | D81: 0.27 | E81: 0.27 | F81: 0.42 | G81: 0.42 | H81: 0.42 | I81: 0.42
A82: A0A8I3Q4P5 | B82: 0.1 | C82: 0.1 | D82: 0.1 | E82: 0.1 | F82: 0.1 | G82: =MEDIAN(F82,I82) -> 0.125 | H82: 0.125 | I82: 0.15
A83: A0A8I3Q0B4 | B83: 0.08 | C83: 0.08 | D83: 0.08 | E83: 0.08 | F83: =MEDIAN(G83:H83) -> 0.175 | G83: 0.27 | H83: 0.08 | I83: 0.175
A84: A0A8I3PZ27 | B84: =MEDIAN(C84:D84) -> 0.045 | C84: 0.06 | D84: 0.03 | E84: 0.045 | F84: 0.03 | G84: 0.03 | H84: 0.03 | I84: 0.03
A85: A0A8I3PX06 | B85: 0.25 | C85: 0.25 | D85: 0.25 | E85: 0.25 | F85: 0.39 | G85: 0.39 | H85: 0.39 | I85: 0.39
A86: A0A8I3PVT9 | B86: 1.46 | C86: 1.46 | D86: 1.46 | E86: 1.46 | F86: =MEDIAN(G86,I86) -> 0.595 | G86: 0.88 | H86: 0.595 | I86: 0.31
A87: A0A8I3PS70 | B87: 0.36 | C87: 0.36 | D87: 0.36 | E87: 0.36 | F87: =MEDIAN(G87:H87) -> 0.23 | G87: 0.23 | H87: 0.23 | I87: 0.23
A88: A0A8I3PRM7 | B88: 0.99 | C88: 0.99 | D88: 0.99 | E88: 0.99 | F88: =MEDIAN(G88,I88) -> 0.415 | G88: 0.51 | H88: 0.415 | I88: 0.32
A89: A0A8I3PNX9 | B89: 3.57 | C89: 3.57 | D89: 3.57 | E89: 3.57 | F89: 1.635 | G89: 1.14 | H89: =MEDIAN(G89,I89) -> 1.635 | I89: 2.13
A90: A0A8I3PKH4 | B90: 0.37 | C90: 0.37 | D90: 0.37 | E90: 0.37 | F90: 1.105 | G90: =MEDIAN(H90:I90) -> 1.105 | H90: 1.6 | I90: 0.61
A91: A0A8I3PK78 | B91: 0.3 | C91: 0.3 | D91: 0.3 | E91: 0.3 | F91: 0.14 | G91: 0.14 | H91: 0.14 | I91: 0.14
A92: A0A8I3PJI1 | B92: 0.24 | C92: 0.24 | D92: 0.24 | E92: 0.24 | F92: 0.15 | G92: 0.15 | H92: 0.15 | I92: 0.15
A93: A0A8I3PHY6 | B93: 0.22 | C93: 0.22 | D93: 0.22 | E93: 0.22 | F93: 0.5 | G93: 0.22 | H93: 0.22 | I93: 0.5
A94: A0A8I3PG86 | B94: 1.95 | C94: 1.95 | D94: 1.95 | E94: 1.95 | F94: 2.54 | G94: 2.54 | H94: 2.54 | I94: 2.54
A95: A0A8I3PED8 | B95: 0.06 | C95: 0.06 | D95: 0.06 | E95: 0.06 | F95: 0.12 | G95: 0.12 | H95: 0.12 | I95: 0.12
A96: A0A8I3PCE5 | B96: 0.39 | C96: 0.39 | D96: 0.39 | E96: 0.39 | F96: 0.63 | G96: 0.63 | H96: 0.63 | I96: 0.63
...

Sheet Edad_VF
A1: Accesion | B1: Muestra 1 | C1: Muestra 3 | D1: Muestra 6 | E1: Muestra 7 | F1: Muestra 2 | G1: Muestra 4 | H1: Muestra 5 | I1: Muestra 8
A2: P49822 | B2: 27.08 | C2: =MEDIAN(B2,D2:E2) -> 14.31 | D2: 14.31 | E2: 11.02 | F2: 7.35 | G2: 8.43 | H2: 12.56 | I2: 6.4
A3: A0A8I3NCQ4 | B3: 0.53 | C3: 0.03 | D3: 0.1 | E3: 0.1 | F3: 0.07 | G3: 0.03 | H3: 0.15 | I3: 0.29
A4: A0A8I3MSG4 | B4: 8.48 | C4: 2.08 | D4: 4.4 | E4: 3.69 | F4: 5.22 | G4: 5.22 | H4: 4.4 | I4: 3.69
A5: A0A8I3N262 | B5: 1.58 | C5: 0.79 | D5: 1.09 | E5: 0.98 | F5: 0.69 | G5: 0.3 | H5: =MEDIAN(F5:G5) -> 0.495 | I5: =MEDIAN(G5:H5) -> 0.3975
A6: A0A8I3NVK3 | B6: 1.53 | C6: 1.21 | D6: 0.7 | E6: 1.21 | F6: 0.7 | G6: 0.7 | H6: 0.94 | I6: 0.7
A7: A0A8I3P684 | B7: 2.75 | C7: 0.74 | D7: 0.74 | E7: 0.25 | F7: 0.25 | G7: 0.74 | H7: 0.74 | I7: 0.74
A8: A0A8I3Q3K3 | B8: 1.59 | C8: 0.92 | D8: 1.47 | E8: 1.35 | F8: 2.87 | G8: 0.83 | H8: 0.74 | I8: 1.59
A9: A0A1K0GGH0 | B9: 27.82 | C9: 9.25 | D9: =MEDIAN(B9:C9,E9) -> 27.82 | E9: 27.82 | F9: 9.25 | G9: 134.97 | H9: 1.81 | I9: 12.27
A10: A0A8I3NFJ3 | B10: 1.4 | C10: 0.75 | D10: 1.05 | E10: 0.75 | F10: 0.89 | G10: 0.89 | H10: 0.89 | I10: 0.61
A11: A0A8I3NL87 | B11: 0.96 | C11: 0.69 | D11: 0.25 | E11: 0.35 | F11: 0.35 | G11: 0.45 | H11: 0.82 | I11: 0.82
A12: A0A8I3P0H1 | B12: 0.27 | C12: 0.05 | D12: 0.11 | E12: =MEDIAN(B12:D12) -> 0.11 | F12: 0.17 | G12: 0.08 | H12: =MEDIAN(F12:G12,I12) -> 0.17 | I12: 0.2
A13: A0A8I3PB96 | B13: 3.32 | C13: 5.23 | D13: 7.97 | E13: 7.97 | F13: 7.97 | G13: 5.23 | H13: 7.97 | I13: 11.94
A14: A0A8I3N9N7 | B14: 0.12 | C14: 0.06 | D14: 0.25 | E14: 0.35 | F14: 0.16 | G14: 0.25 | H14: 0.12 | I14: 0.3
A15: A0A8I3Q4E9 | B15: 1.14 | C15: 0.33 | D15: 1.14 | E15: =MEDIAN(B15:D15) -> 1.14 | F15: 0.61 | G15: 0.61 | H15: 0.61 | I15: 0.61
A16: A0A8I3NHZ1 | B16: 0.87 | C16: 1.15 | D16: 0.87 | E16: 0.74 | F16: 0.87 | G16: 0.41 | H16: 1.15 | I16: 1
A17: A0A8I3P9P7 | B17: 0.65 | C17: 0.65 | D17: 0.65 | E17: 0.65 | F17: 0.46 | G17: 0.46 | H17: 0.46 | I17: 0.46
A18: A0A8I3P1L4 | B18: 0.33 | C18: 0.33 | D18: 0.33 | E18: 0.33 | F18: 0.24 | G18: 0.24 | H18: 0.24 | I18: 0.24
A19: A0A8I3NGP3 | B19: 0.3 | C19: 0.3 | D19: 0.3 | E19: 0.3 | F19: 0.13 | G19: 0.13 | H19: 0.13 | I19: 0.13
A20: A1ILJ0 | B20: 0.44 | C20: 0.73 | D20: 0.9 | E20: 0.73 | F20: 0.58 | G20: 0.44 | H20: 0.9 | I20: 0.58
A21: A0A8I3NR35 | B21: 0.14 | C21: =MEDIAN(B21,D21:E21) -> 0.14 | D21: 0.14 | E21: 0.14 | F21: 0.3 | G21: =MEDIAN(H21:I21,F21) -> 0.3 | H21: 0.3 | I21: 0.39
A22: A0A8I3NBI7 | B22: 0.56 | C22: 0.56 | D22: 0.16 | E22: 0.16 | F22: 0.45 | G22: =MEDIAN(H22:I22,F22) -> 0.56 | H22: 0.81 | I22: 0.56
A23: A0A8I3PIK8 | B23: 0.53 | C23: 0.38 | D23: 0.53 | E23: 0.38 | F23: 0.38 | G23: 0.38 | H23: 0.38 | I23: 0.38
A24: A0A5B8JID5 | B24: 2.88 | C24: 2.88 | D24: 2.88 | E24: 2.88 | F24: 4.09 | G24: =MEDIAN(F24,I24) -> 2.405 | H24: 2.405 | I24: 0.72
A25: A0A8I3NAM6 | B25: 2.72 | C25: 8.98 | D25: 2.72 | E25: =MEDIAN(B25:D25) -> 2.72 | F25: 2.72 | G25: 2.72 | H25: 2.72 | I25: 2.72
A26: A0A8I3PBR7 | B26: 0.54 | C26: 0.68 | D26: 0.83 | E26: 0.41 | F26: 0.68 | G26: 0.54 | H26: 0.41 | I26: 0.54
A27: A0A8I3N8K2 | B27: 0.32 | C27: 0.32 | D27: 0.32 | E27: 0.32 | F27: 0.52 | G27: 0.32 | H27: =MEDIAN(F27:G27,I27) -> 0.32 | I27: 0.32
A28: A0A8I3RX37 | B28: 0.12 | C28: 0.19 | D28: =MEDIAN(B28:C28,E28) -> 0.12 | E28: 0.09 | F28: =MEDIAN(G28:I28) -> 0.22 | G28: 0.06 | H28: 0.26 | I28: 0.22
A29: A0A8I3NYI8 | B29: 0.22 | C29: 0.22 | D29: 0.22 | E29: 0.22 | F29: 0.34 | G29: 0.34 | H29: 0.34 | I29: 0.34
A30: A0A8I3NZ15 | B30: 0.47 | C30: =MEDIAN(B30,D30:E30) -> 1.6 | D30: 1.6 | E30: 2.81 | F30: =MEDIAN(G30,I30) -> 0.96 | G30: 1.15 | H30: 0.96 | I30: 0.77
A31: A0A8I3NCJ5 | B31: 0.13 | C31: =MEDIAN(B31,D31:E31) -> 0.27 | D31: 0.34 | E31: 0.27 | F31: 0.19 | G31: 0.13 | H31: 0.13 | I31: 0.61
A32: A0A8I3MQ40 | B32: 0.46 | C32: =MEDIAN(B32,D32) -> 0.355 | D32: 0.25 | E32: 0.355 | F32: 0.16 | G32: 0.16 | H32: 0.16 | I32: 0.16
A33: A0A8I3NTB5 | B33: 0.19 | C33: 0.19 | D33: 0.19 | E33: 0.19 | F33: 0.14 | G33: =MEDIAN(F33,H33) -> 0.115 | H33: 0.09 | I33: 0.115
A34: A0A8I3P8J2 | B34: 0.36 | C34: 0.17 | D34: 0.36 | E34: 0.17 | F34: 0.36 | G34: 0.36 | H34: 0.36 | I34: 0.47
A35: A0A8I3MYH9 | B35: 0.03 | C35: =MEDIAN(B35,D35:E35) -> 0.03 | D35: 0.04 | E35: 0.03 | F35: 0.05 | G35: 0.03 | H35: 0.03 | I35: 0.03
A36: O18840 | B36: 0.66 | C36: =MEDIAN(B36,D36) -> 0.955 | D36: 1.25 | E36: 0.955 | F36: 1.49 | G36: =MEDIAN(F36,H36) -> 1.165 | H36: 0.84 | I36: 1.165
A37: A0A8I3NCZ8 | B37: 0.27 | C37: 0.2 | D37: 0.44 | E37: 0.2 | F37: 0.35 | G37: 0.13 | H37: 0.13 | I37: 0.27
A38: P18649 | B38: 0.41 | C38: 0.41 | D38: 0.41 | E38: 0.41 | F38: 0.41 | G38: 0.41 | H38: 0.26 | I38: 0.41
A39: A0A8I3NP20 | B39: 0.12 | C39: 0.12 | D39: 0.12 | E39: 0.12 | F39: 0.5 | G39: 0.5 | H39: 0.5 | I39: 0.5
A40: Q29393 | B40: 0.7 | C40: 0.37 | D40: =MEDIAN(B40:C40) -> 0.535 | E40: 0.535 | F40: 1.1 | G40: 1.1 | H40: 1.1 | I40: 1.1
...

Sheet Supervivencia_VF
A1: Accesion | B1: Muestra 2 | C1: Muestra 4 | D1: Muestra 6 | E1: Muestra 8 | F1: Muestra 3 | G1: Muestra 5 | H1: Muestra 7
A2: P49822 | B2: 7.35 | C2: 8.43 | D2: 14.31 | E2: 6.4 | F2: =MEDIAN(G2:H2) -> 11.79 | G2: 12.56 | H2: 11.02
A3: A0A8I3NCQ4 | B3: 0.07 | C3: 0.03 | D3: 0.1 | E3: 0.29 | F3: 0.03 | G3: 0.15 | H3: 0.1
A4: A0A8I3MSG4 | B4: 5.22 | C4: 5.22 | D4: 4.4 | E4: 3.69 | F4: 2.08 | G4: 4.4 | H4: 3.69
A5: A0A8I3N262 | B5: 0.69 | C5: 0.3 | D5: 1.09 | E5: =MEDIAN(B5:D5) -> 0.69 | F5: 0.79 | G5: =MEDIAN(F5,H5) -> 0.885 | H5: 0.98
A6: A0A8I3NVK3 | B6: 0.7 | C6: 0.7 | D6: 0.7 | E6: 0.7 | F6: 1.21 | G6: 0.94 | H6: 1.21
A7: A0A8I3P684 | B7: 0.25 | C7: 0.74 | D7: 0.74 | E7: 0.74 | F7: 0.74 | G7: 0.74 | H7: 0.25
A8: A0A8I3Q3K3 | B8: 2.87 | C8: 0.83 | D8: 1.47 | E8: 1.59 | F8: 0.92 | G8: 0.74 | H8: 1.35
A9: A0A1K0GGH0 | B9: 9.25 | C9: 134.97 | D9: =MEDIAN(B9:C9,E9) -> 12.27 | E9: 12.27 | F9: 9.25 | G9: 1.81 | H9: 27.82
A10: A0A8I3NFJ3 | B10: 0.89 | C10: 0.89 | D10: 1.05 | E10: 0.61 | F10: 0.75 | G10: 0.89 | H10: 0.75
A11: A0A8I3NL87 | B11: 0.35 | C11: 0.45 | D11: 0.25 | E11: 0.82 | F11: 0.69 | G11: 0.82 | H11: 0.35
A12: A0A8I3P0H1 | B12: 0.17 | C12: 0.08 | D12: 0.11 | E12: 0.2 | F12: 0.05 | G12: 0.05 | H12: 0.05
A13: A0A8I3PB96 | B13: 7.97 | C13: 5.23 | D13: 7.97 | E13: 11.94 | F13: 5.23 | G13: 7.97 | H13: 7.97
A14: A0A8I3N9N7 | B14: 0.16 | C14: 0.25 | D14: 0.25 | E14: 0.3 | F14: 0.06 | G14: 0.12 | H14: 0.35
A15: A0A8I3Q4E9 | B15: 1.14 | C15: 1.14 | D15: 1.14 | E15: 1.14 | F15: 0.33 | G15: 0.61 | H15: =MEDIAN(F15:G15) -> 0.47
A16: A0A8I3NHZ1 | B16: 0.87 | C16: 0.41 | D16: 0.87 | E16: 1 | F16: 1.15 | G16: 1.15 | H16: 0.74
A17: A1ILJ0 | B17: 0.58 | C17: 0.44 | D17: 0.9 | E17: 0.58 | F17: 0.73 | G17: 0.9 | H17: 0.73
A18: A0A8I3NR35 | B18: 0.3 | C18: 0.3 | D18: 0.14 | E18: 0.39 | F18: =MEDIAN(G18:H18) -> 0.22 | G18: 0.3 | H18: 0.14
A19: E2RE76 | B19: 0.22 | C19: 0.22 | D19: 0.22 | E19: 0.22 | F19: 0.49 | G19: 0.49 | H19: 0.49
A20: A0A8I3NBI7 | B20: 0.45 | C20: 0.45 | D20: 0.16 | E20: 0.56 | F20: 0.56 | G20: 0.81 | H20: 0.16
A21: A0A8I3PIK8 | B21: 0.38 | C21: 0.38 | D21: 0.53 | E21: 0.38 | F21: 0.38 | G21: 0.38 | H21: 0.38
A22: A0A8I3NAM6 | B22: 2.72 | C22: 2.72 | D22: 2.72 | E22: 2.72 | F22: 8.98 | G22: 2.72 | H22: =MEDIAN(F22:G22) -> 5.85
A23: A0A8I3PBR7 | B23: 0.68 | C23: 0.54 | D23: 0.83 | E23: 0.54 | F23: 0.68 | G23: 0.41 | H23: 0.41
A24: A0A8I3RX37 | B24: 0.14 | C24: 0.06 | D24: =MEDIAN(C24,E24) -> 0.14 | E24: 0.22 | F24: 0.19 | G24: 0.26 | H24: 0.09
A25: A0A8I3NYI8 | B25: 0.34 | C25: 0.34 | D25: 0.34 | E25: 0.34 | F25: 0.22 | G25: 0.22 | H25: 0.22
A26: A0A8I3NZ15 | B26: =MEDIAN(C26:E26) -> 1.15 | C26: 1.15 | D26: 1.6 | E26: 0.77 | F26: 2.81 | G26: 2.81 | H26: 2.81
A27: A0A8I3NCJ5 | B27: 0.19 | C27: 0.13 | D27: 0.34 | E27: 0.61 | F27: =MEDIAN(G27:H27) -> 0.2 | G27: 0.13 | H27: 0.27
A28: A0A8I3MQ40 | B28: 0.16 | C28: 0.16 | D28: 0.25 | E28: 0.16 | F28: 0.16 | G28: 0.16 | H28: 0.16
A29: A0A8I3NTB5 | B29: 0.14 | C29: 0.14 | D29: 0.14 | E29: 0.14 | F29: 0.09 | G29: 0.09 | H29: 0.09
A30: A0A8I3P8J2 | B30: 0.36 | C30: 0.36 | D30: 0.36 | E30: 0.47 | F30: 0.17 | G30: 0.36 | H30: 0.17
A31: A0A8I3MYH9 | B31: 0.05 | C31: 0.04 | D31: 0.04 | E31: 0.03 | F31: 0.03 | G31: 0.03 | H31: 0.03
A32: O18840 | B32: 1.49 | C32: =MEDIAN(B32,D32) -> 1.37 | D32: 1.25 | E32: 1.37 | F32: 0.84 | G32: 0.84 | H32: 0.84
A33: A0A8I3NCZ8 | B33: 0.35 | C33: 0.13 | D33: 0.44 | E33: 0.27 | F33: 0.2 | G33: 0.13 | H33: 0.2
A34: P18649 | B34: 0.41 | C34: 0.41 | D34: 0.41 | E34: 0.41 | F34: 0.26 | G34: 0.26 | H34: 0.26
A35: A0A8I3Q4C1 | B35: 0.22 | C35: 0.3 | D35: 0.3 | E35: 0.39 | F35: 0.22 | G35: 0.14 | H35: 0.69
A36: A0A8I3N6K0 | B36: 0.03 | C36: 0.06 | D36: 0.03 | E36: 0.03 | F36: 0.03 | G36: 0.06 | H36: =MEDIAN(F36:G36) -> 0.045
A37: A0A8I3NBI4 | B37: 0.19 | C37: 0.19 | D37: 0.19 | E37: 0.19 | F37: =MEDIAN(G37:H37) -> 0.14 | G37: 0.09 | H37: 0.19
A38: A0A8I3Q0F7 | B38: 0.44 | C38: =MEDIAN(D38:E38) -> 0.44 | D38: 0.19 | E38: 0.69 | F38: 0.3 | G38: 0.3 | H38: 0.3
A39: A0A8I3MIR0 | B39: 1.08 | C39: 1.08 | D39: 1.08 | E39: 1.08 | F39: 0.63 | G39: 0.63 | H39: 0.63
A40: A0A8I3PUT3 | B40: 0.07 | C40: =MEDIAN(B40,D40) -> 0.06 | D40: 0.05 | E40: 0.06 | F40: 0.05 | G40: =MEDIAN(F40,H40) -> 0.085 | H40: 0.12
...

Sheet Resultados sexo
B1: Accesion | C1: Uniprot-API | D1: Ensembl | E1: logFC | F1: AveExpr | G1: t | H1: P.Value | I1: adj.P.Val | J1: B | K1: Regulacion
A2: 3 | B2: A0A8I3MJP4 | C2: =VLOOKUP(B2,'Uniprot-API'!$A$1:$D$165,2,) -> ALDOA | D2: =VLOOKUP(B2,'BiomaRt Ensembl'!$A$1:$F$327,2,) -> #N/A | E2: -1.9033853 | F2: -1.3378666 | G2: -21.793259 | H2: 3.8223427e-08 | I2: 1.7710188e-06 | J2: 9.6479256 | K2: Down en Hembra
A3: 5 | B3: A0A5B8JID5 | C3: =VLOOKUP(B3,'Uniprot-API'!$A$1:$D$165,2,) -> 0 | D3: =VLOOKUP(B3,'BiomaRt Ensembl'!$A$1:$F$327,2,) -> 0 | E3: -2.3312731 | F3: 0.65319844 | G3: -16.918985 | H3: 2.5422982e-07 | I3: 7.067589e-06 | J3: 7.6518822 | K3: Down en Hembra
A4: 6 | B4: A0A8I3NGP3 | C4: =VLOOKUP(B4,'Uniprot-API'!$A$1:$D$165,2,) -> C3 | D4: =VLOOKUP(B4,'BiomaRt Ensembl'!$A$1:$F$327,2,) -> #N/A | E4: -1.2732008 | F4: -2.344414 | G4: -14.723245 | H4: 7.1321171e-07 | I4: 1.4630295e-05 | J4: 6.5424712 | K4: Down en Hembra
A5: 7 | B5: A0A8I3NVY9 | C5: =VLOOKUP(B5,'Uniprot-API'!$A$1:$D$165,2,) -> NME2 | D5: =VLOOKUP(B5,'BiomaRt Ensembl'!$A$1:$F$327,2,) -> NME2 | E5: -1.2597338 | F5: -1.2448265 | G5: -14.357289 | H5: 8.5893164e-07 | I5: 1.4630295e-05 | J5: 6.3412469 | K5: Down en Hembra
A6: 8 | B6: A0A8I3P237 | C6: =VLOOKUP(B6,'Uniprot-API'!$A$1:$D$165,2,) -> TALDO1 | D6: =VLOOKUP(B6,'BiomaRt Ensembl'!$A$1:$F$327,2,) -> TALDO1 | E6: -1.2369696 | F6: -1.4785152 | G6: -14.249999 | H6: 9.0781072e-07 | I6: 1.4630295e-05 | J6: 6.281275 | K6: Down en Hembra
A7: 10 | B7: A0A8I3PK78 | C7: =VLOOKUP(B7,'Uniprot-API'!$A$1:$D$165,2,) -> KRT75 | D7: =VLOOKUP(B7,'BiomaRt Ensembl'!$A$1:$F$327,2,) -> #N/A | E7: -1.1663648 | F7: -2.290996 | G7: -13.511838 | H7: 1.3430782e-06 | I7: 1.8668787e-05 | J7: 5.8560406 | K7: Down en Hembra
A8: 26 | B8: A0A8I3PRM7 | C8: =VLOOKUP(B8,'Uniprot-API'!$A$1:$D$165,2,) -> TPI1 | D8: =VLOOKUP(B8,'BiomaRt Ensembl'!$A$1:$F$327,2,) -> TPI1 | E8: -1.3408976 | F8: -0.65613143 | G8: -7.4360048 | H8: 9.429897e-05 | I8: 0.0005041368 | J8: 1.1867581 | K8: Down en Hembra
A9: 27 | B9: A0A8I3PNX9 | C9: =VLOOKUP(B9,'Uniprot-API'!$A$1:$D$165,2,) -> COQ10B | D9: =VLOOKUP(B9,'BiomaRt Ensembl'!$A$1:$F$327,2,) -> COQ10B | E9: -1.2286332 | F9: 1.2503191 | G9: -7.3731063 | H9: 9.9896372e-05 | I9: 0.00051428132 | J9: 1.1231889 | K9: Down en Hembra
A10: 28 | B10: P33703 | C10: =VLOOKUP(B10,'Uniprot-API'!$A$1:$D$165,2,) -> APOH | D10: =VLOOKUP(B10,'BiomaRt Ensembl'!$A$1:$F$327,2,) -> APOH | E10: -1.2815303 | F10: -1.1059998 | G10: -7.2196865 | H10: 0.00011517008 | I10: 0.00055209212 | J10: 0.96635752 | K10: Down en Hembra
A11: 41 | B11: A0A8I3MS75 | C11: =VLOOKUP(B11,'Uniprot-API'!$A$1:$D$165,2,) -> LGALS7B | D11: =VLOOKUP(B11,'BiomaRt Ensembl'!$A$1:$F$327,2,) -> ACTN4 | E11: -1.4873233 | F11: -2.9370996 | G11: -5.7330978 | H11: 0.00052174165 | I11: 0.0017688314 | J11: -0.69566666 | K11: Down en Hembra
A12: 47 | B12: A0A8I3P7T5 | C12: =VLOOKUP(B12,'Uniprot-API'!$A$1:$D$165,2,) -> ANXA2 | D12: =VLOOKUP(B12,'BiomaRt Ensembl'!$A$1:$F$327,2,) -> ANXA2 | E12: -1.29985 | F12: -1.2813891 | G12: -4.6738132 | H12: 0.0018136908 | I12: 0.0053638941 | J12: -2.0571356 | K12: Down en Hembra
A13: 49 | B13: A0A8I3PVT9 | C13: =VLOOKUP(B13,'Uniprot-API'!$A$1:$D$165,2,) -> ENO1 | D13: =VLOOKUP(B13,'BiomaRt Ensembl'!$A$1:$F$327,2,) -> ENO1 | E13: -1.4562075 | F13: -0.15336534 | G13: -4.4320962 | H13: 0.002464616 | I13: 0.0069914617 | J13: -2.3901005 | K13: Down en Hembra
A14: 13 | B14: A0A8I3P6H2 | E14: 0.99399002 | F14: -0.91258459 | G14: 11.413916 | H14: 4.6036746e-06 | I14: 4.9223906e-05 | J14: 4.5108157 | K14: No significativo
A15: 52 | B15: A0A8I3NCX8 | C15: =VLOOKUP(B15,'Uniprot-API'!$A$1:$D$165,2,) -> LOC100855903 | D15: =VLOOKUP(B15,'BiomaRt Ensembl'!$A$1:$F$327,2,) -> #N/A | E15: -1.5366622 | F15: -0.59194366 | G15: -3.5075633 | H15: 0.0086247547 | I15: 0.023054633 | J15: -3.7365266 | K15: Down en Hembra
A16: 15 | B16: A0A8I3PED8 | E16: 0.93142077 | F16: -3.5621096 | G16: 9.6587905 | H16: 1.5266881e-05 | I16: 0.0001414731 | J16: 3.1936965 | K16: No significativo
A17: 16 | B17: A0A8I3P1Z4 | E17: 0.82523096 | F17: -2.3941845 | G17: 9.5248615 | H17: 1.6858121e-05 | I17: 0.00014645493 | J17: 3.084537 | K17: No significativo
A18: 17 | B18: A0A8I3NNP1 | E18: -0.77577915 | F18: -0.93677006 | G18: -8.6879868 | H18: 3.222834e-05 | I18: 0.0002326305 | J18: 2.3705478 | K18: No significativo
A19: 18 | B19: A0A8I3S0B7 | E19: -0.74518 | F19: -1.9873242 | G19: -8.6755778 | H19: 3.2552204e-05 | I19: 0.0002326305 | J19: 2.3595254 | K19: No significativo
A20: 19 | B20: A0A8I3MKL7 | E20: -0.74518 | F20: -1.9873242 | G20: -8.6755778 | H20: 3.2552204e-05 | I20: 0.0002326305 | J20: 2.3595254 | K20: No significativo
A21: 20 | B21: A0A8I3PJI1 | E21: -0.74508991 | F21: -2.4021664 | G21: -8.5970728 | H21: 3.4687557e-05 | I21: 0.0002326305 | J21: 2.2894831 | K21: No significativo
A22: 21 | B22: A0A8I3NP66 | E22: -0.75073989 | F22: -1.2623623 | G22: -8.5639386 | H22: 3.5635511e-05 | I22: 0.0002326305 | J22: 2.2597592 | K22: No significativo
A23: 22 | B23: A0A8I3P9E1 | E23: -0.73448898 | F23: -2.2270077 | G23: -8.5239227 | H23: 3.6819216e-05 | I23: 0.0002326305 | J23: 2.223733 | K23: No significativo
A24: 23 | B24: A0A8I3NY33 | E24: -0.72606327 | F24: -2.0708452 | G24: -8.4490333 | H24: 3.9154643e-05 | I24: 0.00023663023 | J24: 2.1559284 | K24: No significativo
A25: 24 | B25: A0A8I3PS70 | E25: -0.7135151 | F25: -1.8016168 | G25: -8.2954393 | H25: 4.448155e-05 | I25: 0.00025762231 | J25: 2.0152855 | K25: No significativo
A26: 25 | B26: A0A8I3MJ33 | E26: 0.90987679 | F26: 2.0097285 | G26: 7.8440573 | H26: 6.5461588e-05 | I26: 0.00036396643 | J26: 1.5892153 | K26: No significativo
A27: 54 | B27: A0A1B1X468 | C27: =VLOOKUP(B27,'Uniprot-API'!$A$1:$D$165,2,) -> 0 | D27: =VLOOKUP(B27,'BiomaRt Ensembl'!$A$1:$F$327,2,) -> #N/A | E27: -1.0031197 | F27: -1.4800091 | G27: -3.4304183 | H27: 0.0096282904 | I27: 0.024783933 | J27: -3.8534987 | K27: Down en Hembra
A28: 57 | B28: A0A8I3MWF5 | C28: =VLOOKUP(B28,'Uniprot-API'!$A$1:$D$165,2,) -> VCP | D28: =VLOOKUP(B28,'BiomaRt Ensembl'!$A$1:$F$327,2,) -> VCP | E28: -1.4865506 | F28: -2.4697976 | G28: -3.1637167 | H28: 0.014171513 | I28: 0.034558602 | J28: -4.2620294 | K28: Down en Hembra
A29: 1 | B29: A0A8I3RZV0 | C29: =VLOOKUP(B29,'Uniprot-API'!$A$1:$D$165,2,) -> 0 | D29: =VLOOKUP(B29,'BiomaRt Ensembl'!$A$1:$F$327,2,) -> #N/A | E29: 2.3440168 | F29: -0.63530652 | G29: 25.751997 | H29: 1.0872364e-08 | I29: 1.4529597e-06 | J29: 10.930308 | K29: Up en Hembra
A30: 29 | B30: A0A8I3NSK4 | E30: 0.63606945 | F30: -1.1674551 | G30: 7.2195509 | H30: 0.00011518469 | I30: 0.00055209212 | J30: 0.96621779 | K30: No significativo
A31: 30 | B31: A0A8I3NTB5 | E31: -0.8604253 | F31: -3.0808237 | G31: -7.0748001 | H31: 0.0001320178 | I31: 0.00061168248 | J31: 0.81589312 | K31: No significativo
A32: 31 | B32: A0A8I3PCE5 | E32: 0.62435833 | F32: -1.0172337 | G32: 7.0260875 | H32: 0.00013828552 | I32: 0.00062005442 | J32: 0.76478168 | K32: No significativo
A33: 32 | B33: A0A8I3S396 | E33: 0.5845109 | F33: -1.5150595 | G33: 6.7430716 | H33: 0.00018195106 | I33: 0.00079034993 | J33: 0.46248768 | K33: No significativo
A34: 33 | B34: A0A8I3PX06 | E34: 0.57396045 | F34: -1.6837716 | G34: 6.6566628 | H34: 0.00019819262 | I34: 0.00083481133 | J34: 0.36833806 | K34: No significativo
A35: 34 | B35: A0A8I3Q5N9 | E35: 0.56986066 | F35: -1.5748329 | G35: 6.5879489 | H35: 0.00021226174 | I35: 0.00086777592 | J35: 0.29283555 | K35: No significativo
A36: 35 | B36: A0A8I3NYI8 | E36: 0.56042137 | F36: -1.8748871 | G36: 6.5215968 | H36: 0.00022690798 | I36: 0.00090114882 | J36: 0.21939019 | K36: No significativo
A37: 36 | B37: A0A8I3P9P7 | E37: -0.56609268 | F37: -0.87564158 | G37: -6.3159502 | H37: 0.00027992831 | I37: 0.0010578422 | J37: -0.011654949 | K37: No significativo
A38: 37 | B38: A0A8I3N8Y1 | E38: 0.54241328 | F38: -2.0952917 | G38: 6.3102437 | H38: 0.00028158389 | I38: 0.0010578422 | J38: -0.018140875 | K38: No significativo
A39: 38 | B39: A0A8I3P1L4 | E39: -0.52664622 | F39: -1.8336769 | G39: -6.1257171 | H39: 0.00034144587 | I39: 0.0012489731 | J39: -0.23008015 | K39: No significativo
A40: 2 | B40: A0A8I3N4C3 | C40: =VLOOKUP(B40,'Uniprot-API'!$A$1:$D$165,2,) -> CALD1 | D40: =VLOOKUP(B40,'BiomaRt Ensembl'!$A$1:$F$327,2,) -> CALD1 | E40: 2.0313675 | F40: -1.7911162 | G40: 23.612951 | H40: 2.0905895e-08 | I40: 1.4529597e-06 | J40: 10.268435 | K40: Up en Hembra
...

Sheet Resultados edad
B1: Accesion | C1: Uniprot-API | D1: Ensembl | E1: logFC | F1: AveExpr | G1: t | H1: P.Value | I1: adj.P.Val | J1: B | K1: Regulacion
A2: 5 | B2: A0A8I3NGP3 | C2: =VLOOKUP(B2,'Uniprot-API'!$A$1:$D$165,2,) -> C3 | D2: =VLOOKUP(B2,'BiomaRt Ensembl'!$A$1:$F$327,2,) -> #N/A | E2: -1.4853952 | F2: -2.3768149 | G2: -14.445806 | H2: 5.0169029e-07 | I2: 1.4049087e-05 | J2: 7.0258757 | K2: Down en Geriatrico
A3: 6 | B3: A0A8I3P6H2 | C3: =VLOOKUP(B3,'Uniprot-API'!$A$1:$D$165,2,) -> MPO | D3: =VLOOKUP(B3,'BiomaRt Ensembl'!$A$1:$F$327,2,) -> #N/A | E3: -1.3409413 | F3: -0.94498554 | G3: -14.12263 | H3: 5.978335e-07 | I3: 1.4049087e-05 | J3: 6.8434893 | K3: Down en Geriatrico
A4: 7 | B4: E2R6K5 | C4: =VLOOKUP(B4,'Uniprot-API'!$A$1:$D$165,2,) -> GALK1 | D4: =VLOOKUP(B4,'BiomaRt Ensembl'!$A$1:$F$327,2,) -> H3-3A | E4: -1.7242309 | F4: 0.21117923 | G4: -13.569642 | H4: 8.1416303e-07 | I4: 1.639957e-05 | J4: 6.520949 | K4: Down en Geriatrico
A5: 8 | B5: A0A8I3PED8 | C5: =VLOOKUP(B5,'Uniprot-API'!$A$1:$D$165,2,) -> FN1 | D5: =VLOOKUP(B5,'BiomaRt Ensembl'!$A$1:$F$327,2,) -> FN1 | E5: -1.2783721 | F5: -3.5945106 | G5: -11.208201 | H5: 3.5206113e-06 | I5: 6.2050774e-05 | J5: 4.9732296 | K5: Down en Geriatrico
A6: 9 | B6: A0A8I3NTB5 | C6: =VLOOKUP(B6,'Uniprot-API'!$A$1:$D$165,2,) -> CANT1 | D6: =VLOOKUP(B6,'BiomaRt Ensembl'!$A$1:$F$327,2,) -> #N/A | E6: -1.0208734 | F6: -2.8032389 | G6: -9.9495932 | H6: 8.6393532e-06 | I6: 0.00013534987 | J6: 4.0125354 | K6: Down en Geriatrico
A7: 21 | B7: A0A8I3MQ40 | C7: =VLOOKUP(B7,'Uniprot-API'!$A$1:$D$165,2,) -> SERPINA5 | D7: =VLOOKUP(B7,'BiomaRt Ensembl'!$A$1:$F$327,2,) -> SERPINA5 | E7: -1.3958253 | F7: -2.1222475 | G7: -7.7834629 | H7: 5.2360235e-05 | I7: 0.00035156157 | J7: 2.0676301 | K7: Down en Geriatrico
A8: 27 | B8: A0A8I3P1P3 | C8: =VLOOKUP(B8,'Uniprot-API'!$A$1:$D$165,2,) -> SERPINB1 | D8: =VLOOKUP(B8,'BiomaRt Ensembl'!$A$1:$F$327,2,) -> SERPINB1 | E8: -1.1971722 | F8: -1.3584529 | G8: -6.1487038 | H8: 0.00027125597 | I8: 0.0014165589 | J8: 0.28409355 | K8: Down en Geriatrico
A9: 28 | B9: A0A8I3N371 | C9: =VLOOKUP(B9,'Uniprot-API'!$A$1:$D$165,2,) -> H2BC26 | D9: =VLOOKUP(B9,'BiomaRt Ensembl'!$A$1:$F$327,2,) -> #N/A | E9: -1.3403998 | F9: 0.65255941 | G9: -6.0501071 | H9: 0.00030246629 | I9: 0.0015231338 | J9: 0.16605205 | K9: Down en Geriatrico
A10: 30 | B10: A0A8I3N262 | C10: =VLOOKUP(B10,'Uniprot-API'!$A$1:$D$165,2,) -> DHODH | D10: =VLOOKUP(B10,'BiomaRt Ensembl'!$A$1:$F$327,2,) -> DHODH | E10: -1.5375754 | F10: -0.56252418 | G10: -5.634001 | H10: 0.00048550278 | I10: 0.0022818631 | J10: -0.34648623 | K10: Down en Geriatrico
A11: 32 | B11: A0A8I3MEU8 | C11: =VLOOKUP(B11,'Uniprot-API'!$A$1:$D$165,2,) -> NPM1 | D11: =VLOOKUP(B11,'BiomaRt Ensembl'!$A$1:$F$327,2,) -> NPM1 | E11: -1.2856069 | F11: -1.1014138 | G11: -5.51084 | H11: 0.00056093112 | I11: 0.0024716027 | J11: -0.50274525 | K11: Down en Geriatrico
A12: 11 | B12: A0A8I3S0B7 | E12: -0.95737433 | F12: -2.0197252 | G12: -9.2922856 | H12: 1.4370219e-05 | I12: 0.00018420008 | J12: 3.4651047 | K12: No significativo
A13: 12 | B13: A0A8I3PCE5 | E13: -0.97130964 | F13: -1.0496347 | G13: -8.782916 | H13: 2.1778593e-05 | I13: 0.00023606268 | J13: 3.016583 | K13: No significativo
A14: 13 | B14: A0A8I3PHY6 | E14: 0.90448463 | F14: -1.6291592 | G14: 8.6080173 | H14: 2.5237655e-05 | I14: 0.00023606268 | J14: 2.8573412 | K14: No significativo
A15: 14 | B15: A0A8I3PAG4 | E15: 0.94898744 | F15: -1.0665443 | G15: 8.5955716 | H15: 2.5506183e-05 | I15: 0.00023606268 | J15: 2.845904 | K15: No significativo
A16: 15 | B16: A0A8I3MHV0 | E16: 0.88995157 | F16: -1.7738637 | G16: 8.5474258 | H16: 2.6575321e-05 | I16: 0.00023606268 | J16: 2.8015255 | K16: No significativo
A17: 16 | B17: A0A8I3RP80 | E17: 0.91943442 | F17: -1.3263498 | G17: 8.5381381 | H17: 2.6787254e-05 | I17: 0.00023606268 | J17: 2.7929399 | K17: No significativo
A18: 17 | B18: A0A8I3MY05 | E18: 0.87198962 | F18: -1.9347677 | G18: 8.4393995 | H18: 2.916042e-05 | I18: 0.00024185995 | J18: 2.7011713 | K18: No significativo
A19: 18 | B19: A0A8I3MKE1 | E19: 0.8267482 | F19: -2.4265656 | G19: 8.0325061 | H19: 4.1737413e-05 | I19: 0.00032228293 | J19: 2.3131925 | K19: No significativo
A20: 19 | B20: A0A8I3PK78 | E20: 0.81941354 | F20: -2.3233969 | G20: 7.9746826 | H20: 4.3971419e-05 | I20: 0.00032228293 | J20: 2.2567384 | K20: No significativo
A21: 20 | B21: A0A8I3MJD4 | E21: 0.82437814 | F21: -1.8066504 | G21: 7.9318027 | H21: 4.571389e-05 | I21: 0.00032228293 | J21: 2.2146564 | K21: No significativo
A22: 41 | B22: A0A8I3SC19 | C22: =VLOOKUP(B22,'Uniprot-API'!$A$1:$D$165,2,) -> PGAM1 | D22: =VLOOKUP(B22,'BiomaRt Ensembl'!$A$1:$F$327,2,) -> PGAM1 | E22: -1.4531199 | F22: -0.31287964 | G22: -3.8135079 | H22: 0.0051099953 | I22: 0.017421686 | J22: -2.8745596 | K22: Down en Geriatrico
A23: 22 | B23: A0A8I3NR35 | E23: 0.91401371 | F23: -2.2760969 | G23: 7.6601394 | H23: 5.8707538e-05 | I23: 0.00037626195 | J23: 1.9436619 | K23: No significativo
A24: 23 | B24: A0A8I3Q5H9 | E24: 0.85635914 | F24: -3.7884986 | G24: 7.2750029 | H24: 8.4725477e-05 | I24: 0.00051940401 | J24: 1.5460132 | K24: No significativo
A25: 24 | B25: A0A8I3P1L4 | E25: -0.73884056 | F25: -1.8660778 | G25: -7.1298249 | H25: 9.766889e-05 | I25: 0.00057380473 | J25: 1.3918528 | K25: No significativo
A26: 25 | B26: A0A8I3P9P7 | E26: -0.77828702 | F26: -0.90804252 | G26: -6.9374635 | H26: 0.00011831676 | I26: 0.00065601836 | J26: 1.1838606 | K26: No significativo
A27: 26 | B27: Q50KA9 | E27: -0.89561098 | F27: 0.36834572 | G27: -6.9154899 | H27: 0.00012096793 | I27: 0.00065601836 | J27: 1.1598261 | K27: No significativo
A28: 53 | B28: P49822 | C28: =VLOOKUP(B28,'Uniprot-API'!$A$1:$D$165,2,) -> ALB | D28: =VLOOKUP(B28,'BiomaRt Ensembl'!$A$1:$F$327,2,) -> #N/A | E28: -1.1838144 | F28: 3.4852478 | G28: -3.1056502 | H28: 0.014490465 | I28: 0.038324218 | J28: -3.9704433 | K28: Down en Geriatrico
A29: 1 | B29: A0A8I3P6W9 | C29: =VLOOKUP(B29,'Uniprot-API'!$A$1:$D$165,2,) -> RRBP1 | D29: =VLOOKUP(B29,'BiomaRt Ensembl'!$A$1:$F$327,2,) -> RRBP1 | E29: 1.9811801 | F29: -3.2260881 | G29: 18.235984 | H29: 8.1364777e-08 | I29: 8.7441699e-06 | J29: 8.8812883 | K29: Up en Geriatrico
A30: 29 | B30: A0A8I3P1Z4 | E30: 0.61303662 | F30: -2.4265854 | G30: 5.9561281 | H30: 0.0003359313 | I30: 0.0016333211 | J30: 0.052339203 | K30: No significativo
A31: 2 | B31: A0A8I3NP20 | C31: =VLOOKUP(B31,'Uniprot-API'!$A$1:$D$165,2,) -> DPYSL2 | D31: =VLOOKUP(B31,'BiomaRt Ensembl'!$A$1:$F$327,2,) -> DPYSL2 | E31: 1.7784076 | F31: -2.0661207 | G31: 17.281639 | H31: 1.2403078e-07 | I31: 8.7441699e-06 | J31: 8.4579962 | K31: Up en Geriatrico
A32: 31 | B32: A0A8I3N7V2 | E32: -0.99959665 | F32: -1.3754357 | G32: -5.572836 | H32: 0.00052146938 | I32: 0.0023718446 | J32: -0.4238246 | K32: No significativo
A33: 3 | B33: A0A8I3NU27 | C33: =VLOOKUP(B33,'Uniprot-API'!$A$1:$D$165,2,) -> 0 | D33: =VLOOKUP(B33,'BiomaRt Ensembl'!$A$1:$F$327,2,) -> #N/A | E33: 1.5499263 | F33: -1.5957993 | G33: 14.715761 | H33: 4.3454979e-07 | I33: 1.4049087e-05 | J33: 7.1749244 | K33: Up en Geriatrico
A34: 33 | B34: A0A8I3NBJ3 | E34: 0.84147711 | F34: 0.45252455 | G34: 4.865831 | H34: 0.0012365139 | I34: 0.0052832867 | J34: -1.3561391 | K34: No significativo
A35: 34 | B35: A0A8I3NM03 | E35: 0.59739952 | F35: -1.3354176 | G35: 4.318706 | H35: 0.0025337311 | I35: 0.010507532 | J35: -2.1266504 | K35: No significativo
A36: 4 | B36: A0A8I3MJP4 | C36: =VLOOKUP(B36,'Uniprot-API'!$A$1:$D$165,2,) -> ALDOA | D36: =VLOOKUP(B36,'BiomaRt Ensembl'!$A$1:$F$327,2,) -> #N/A | E36: 1.556434 | F36: -1.3702675 | G36: 14.510439 | H36: 4.8461641e-07 | I36: 1.4049087e-05 | J36: 7.0618308 | K36: Up en Geriatrico
A37: 36 | B37: Q6EIY9 | E37: 0.83496693 | F37: -2.3156202 | G37: 3.9958705 | H37: 0.0039498744 | I37: 0.015470341 | J37: -2.6007795 | K37: No significativo
A38: 37 | B38: A0A8I3RXV3 | E38: -0.98945158 | F38: -0.86657633 | G38: -3.9149748 | H38: 0.004425247 | I38: 0.016576179 | J38: -2.7217202 | K38: No significativo
A39: 38 | B39: A0A8I3N8Y1 | E39: -0.56847821 | F39: -1.9672495 | G39: -3.9013864 | H39: 0.0045109501 | I39: 0.016576179 | J39: -2.7421154 | K39: No significativo
A40: 39 | B40: A0A8I3NSK4 | E40: 0.42387511 | F40: -1.199856 | G40: 3.8898821 | H40: 0.0045849005 | I40: 0.016576179 | J40: -2.7594005 | K40: No significativo
...

Sheet Resultados supervivencia
B1: Accesion | C1: Uniprot-API | D1: Ensembl | E1: logFC | F1: AveExpr | G1: t | H1: P.Value | I1: adj.P.Val | J1: B | K1: Regulacion
A2: 2 | B2: A0A8I3SC19 | C2: =VLOOKUP(B2,'Uniprot-API'!$A$1:$D$165,2,) -> PGAM1 | D2: =VLOOKUP(B2,'BiomaRt Ensembl'!$A$1:$F$327,2,) -> PGAM1 | E2: -2.1702638 | F2: 0.019657046 | G2: -22.621812 | H2: 1.8835934e-07 | I2: 1.0642303e-05 | J2: 8.2071929 | K2: Down en Corta
A3: 4 | B3: E2R6K5 | C3: =VLOOKUP(B3,'Uniprot-API'!$A$1:$D$165,2,) -> GALK1 | D3: =VLOOKUP(B3,'BiomaRt Ensembl'!$A$1:$F$327,2,) -> H3-3A | E3: -1.5955793 | F3: 0.16186705 | G3: -16.535328 | H3: 1.4144897e-06 | I3: 3.9959335e-05 | J3: 6.0726997 | K3: Down en Corta
A4: 6 | B4: A0A8I3RXV3 | C4: =VLOOKUP(B4,'Uniprot-API'!$A$1:$D$165,2,) -> PSMB3 | D4: =VLOOKUP(B4,'BiomaRt Ensembl'!$A$1:$F$327,2,) -> PSMB3 | E4: -1.4327635 | F4: -0.61827702 | G4: -15.149038 | H4: 2.4743959e-06 | I4: 4.6601123e-05 | J4: 5.4650366 | K4: Down en Corta
A5: 8 | B5: E2RE76 | C5: =VLOOKUP(B5,'Uniprot-API'!$A$1:$D$165,2,) -> APOA4 | D5: =VLOOKUP(B5,'BiomaRt Ensembl'!$A$1:$F$327,2,) -> #N/A | E5: -1.3058382 | F5: -1.6723458 | G5: -13.53433 | H5: 5.06444e-06 | I5: 6.7159919e-05 | J5: 4.6797005 | K5: Down en Corta
A6: 9 | B6: A0A8I3MY05 | C6: =VLOOKUP(B6,'Uniprot-API'!$A$1:$D$165,2,) -> TUBB | D6: =VLOOKUP(B6,'BiomaRt Ensembl'!$A$1:$F$327,2,) -> TUBB | E6: -1.3024836 | F6: -1.9631445 | G6: -13.337994 | H6: 5.5553977e-06 | I6: 6.7159919e-05 | J6: 4.5777529 | K6: Down en Corta
A7: 10 | B7: A0A8I3P6H2 | C7: =VLOOKUP(B7,'Uniprot-API'!$A$1:$D$165,2,) -> MPO | D7: =VLOOKUP(B7,'BiomaRt Ensembl'!$A$1:$F$327,2,) -> #N/A | E7: -1.2122897 | F7: -0.96691989 | G7: -13.196443 | H7: 5.9433557e-06 | I7: 6.7159919e-05 | J7: 4.5033111 | K7: Down en Corta
A8: 12 | B8: A0A8I3PKH4 | C8: =VLOOKUP(B8,'Uniprot-API'!$A$1:$D$165,2,) -> PSMB1 | D8: =VLOOKUP(B8,'BiomaRt Ensembl'!$A$1:$F$327,2,) -> PSMB1 | E8: -1.8802331 | F8: -0.29355745 | G8: -11.559923 | H8: 1.3678924e-05 | I8: 0.00012880987 | J8: 3.5800769 | K8: Down en Corta
A9: 15 | B9: A0A8I3PED8 | C9: =VLOOKUP(B9,'Uniprot-API'!$A$1:$D$165,2,) -> FN1 | D9: =VLOOKUP(B9,'BiomaRt Ensembl'!$A$1:$F$327,2,) -> FN1 | E9: -1.1497204 | F9: -3.6119757 | G9: -10.943081 | H9: 1.9270489e-05 | I9: 0.00014517102 | J9: 3.198688 | K9: Down en Corta
A10: 18 | B10: A0A8I3MS95 | C10: =VLOOKUP(B10,'Uniprot-API'!$A$1:$D$165,2,) -> ACAN | D10: =VLOOKUP(B10,'BiomaRt Ensembl'!$A$1:$F$327,2,) -> ACAN | E10: -1.034425 | F10: -3.6715142 | G10: -8.9282632 | H10: 6.7623624e-05 | I10: 0.00041196361 | J10: 1.7955124 | K10: Down en Corta
A11: 25 | B11: A0A8I3PW93 | C11: =VLOOKUP(B11,'Uniprot-API'!$A$1:$D$165,2,) -> COL6A3 | D11: =VLOOKUP(B11,'BiomaRt Ensembl'!$A$1:$F$327,2,) -> COL6A3 | E11: -1.9808207 | F11: -3.8627102 | G11: -7.2630382 | H11: 0.00023341835 | I11: 0.0010415827 | J11: 0.40600143 | K11: Down en Corta
A12: 28 | B12: A0A8I3N371 | C12: =VLOOKUP(B12,'Uniprot-API'!$A$1:$D$165,2,) -> H2BC26 | D12: =VLOOKUP(B12,'BiomaRt Ensembl'!$A$1:$F$327,2,) -> #N/A | E12: -1.2117481 | F12: 0.63066374 | G12: -6.5335918 | H12: 0.00043274948 | I12: 0.0017464533 | J12: -0.2863095 | K12: Down en Corta
A13: 35 | B13: A0A8I3NZ15 | C13: =VLOOKUP(B13,'Uniprot-API'!$A$1:$D$165,2,) -> PRDX2 | D13: =VLOOKUP(B13,'BiomaRt Ensembl'!$A$1:$F$327,2,) -> PRDX2 | E13: -1.4653431 | F13: 0.75598195 | G13: -5.19828 | H13: 0.0015550019 | I13: 0.0050204346 | J13: -1.7162778 | K13: Down en Corta
... A16: 3 | B16: A0A8I3N284 | C16: =VLOOKUP(B16,'Uniprot-API'!$A$1:$D$165,2,) -> MAP4 | D16: =VLOOKUP(B16,'BiomaRt Ensembl'!$A$1:$F$327,2,) -> MAP4 | E16: 1.846378 | F16: -3.4824814 | G16: 17.677156 | H16: 9.2213001e-07 | I16: 3.4733564e-05 | J16: 6.5337048 | K16: Up en Corta
A17: 16 | B17: A0A8I3MJD4 | E17: 0.95302977 | F17: -1.6739191 | G17: 9.8770508 | H17: 3.6394765e-05 | I17: 0.00025703803 | J17: 2.4889739 | K17: No significativo
A18: 17 | B18: A0A8I3PK78 | E18: 0.94806517 | F18: -2.1910202 | G18: 9.6125593 | H18: 4.302025e-05 | I18: 0.00028595813 | J18: 2.3019285 | K18: No significativo
A19: 5 | B19: A0A8I3Q0B4 | C19: =VLOOKUP(B19,'Uniprot-API'!$A$1:$D$165,2,) -> ITIH4 | D19: =VLOOKUP(B19,'BiomaRt Ensembl'!$A$1:$F$327,2,) -> #N/A | E19: 1.6026983 | F19: -2.623527 | G19: 15.943841 | H19: 1.7854618e-06 | I19: 4.0351437e-05 | J19: 5.8202725 | K19: Up en Corta
A20: 19 | B20: A0A8I3PCE5 | E20: -0.842658 | F20: -1.0451668 | G20: -8.8931293 | H20: 6.9268218e-05 | I20: 0.00041196361 | J20: 1.7685877 | K20: No significativo
A21: 20 | B21: A0A8I3PAS0 | E21: -0.83657535 | F21: -1.8093566 | G21: -8.6229784 | H21: 8.3557752e-05 | I21: 0.0004721013 | J21: 1.5583769 | K21: No significativo
A22: 21 | B22: A0A8I3S0B7 | E22: -0.8287227 | F22: -2.0142619 | G22: -8.4676852 | H22: 9.3283925e-05 | I22: 0.00050195636 | J22: 1.4349235 | K22: No significativo
A23: 22 | B23: A0A8I3NK76 | E23: -0.81344357 | F23: -2.7572951 | G23: -8.0444972 | H23: 0.00012706146 | I23: 0.00065263385 | J23: 1.08833 | K23: No significativo
A24: 23 | B24: A0A8I3Q620 | E24: 0.74314731 | F24: 0.61155534 | G24: 7.5154997 | H24: 0.00019070194 | I24: 0.00093692694 | J24: 0.6327745 | K24: No significativo
A25: 24 | B25: A0A8I3RR88 | E25: -0.73561665 | F25: -2.2060874 | G25: -7.4535955 | H25: 0.0002002877 | I25: 0.00094302124 | J25: 0.57774815 | K25: No significativo
A26: 7 | B26: P00011 | C26: =VLOOKUP(B26,'Uniprot-API'!$A$1:$D$165,2,) -> CYCS | D26: =VLOOKUP(B26,'BiomaRt Ensembl'!$A$1:$F$327,2,) -> CYCS | E26: 1.452683 | F26: 0.96151452 | G26: 14.323829 | H26: 3.534247e-06 | I26: 5.7052844e-05 | J26: 5.0750388 | K26: Up en Corta
A27: 26 | B27: A0A8I3MJ33 | E27: 0.82633408 | F27: 2.1010092 | G27: 7.2306098 | H27: 0.0002396562 | I27: 0.0010415827 | J27: 0.37641344 | K27: No significativo
A28: 27 | B28: A0A8I3MIR0 | E28: 0.62659098 | F28: -0.20559592 | G28: 6.578913 | H28: 0.00041582836 | I28: 0.0017403187 | J28: -0.24160228 | K28: No significativo
A29: 11 | B29: A0A8I3NPS8 | C29: =VLOOKUP(B29,'Uniprot-API'!$A$1:$D$165,2,) -> YBX1 | D29: =VLOOKUP(B29,'BiomaRt Ensembl'!$A$1:$F$327,2,) -> YBX1 | E29: 1.1268945 | F29: -1.1417954 | G29: 11.696404 | H29: 1.2708801e-05 | I29: 0.00012880987 | J29: 3.6618156 | K29: Up en Corta
A30: 29 | B30: A0A8I3NVK3 | E30: -0.81900117 | F30: -0.2115884 | G30: -6.1116466 | H30: 0.00063395824 | I30: 0.0024702511 | J30: -0.71402147 | K30: No significativo
A31: 30 | B31: A0A8I3N3S4 | E31: 0.53174551 | F31: -0.98899511 | G31: 5.6163577 | H31: 0.0010182473 | I31: 0.003835398 | J31: -1.2439424 | K31: No significativo
A32: 13 | B32: A0A8I3PAG4 | C32: =VLOOKUP(B32,'Uniprot-API'!$A$1:$D$165,2,) -> RBP4 | D32: =VLOOKUP(B32,'BiomaRt Ensembl'!$A$1:$F$327,2,) -> RBP4 | E32: 1.0776391 | F32: -0.92491228 | G32: 11.390178 | H32: 1.5006249e-05 | I32: 0.00013043893 | J32: 3.4771076 | K32: Up en Corta
A33: 32 | B33: O18840 | E33: 0.5519496 | F33: 0.16673212 | G33: 5.4371883 | H33: 0.0012175011 | I33: 0.0042993008 | J33: -1.4434721 | K33: No significativo
A34: 33 | B34: A0A8I3S2Z8 | E34: 0.52688032 | F34: -1.9174331 | G34: 5.4061014 | H34: 0.0012563627 | I34: 0.0043020904 | J34: -1.4785293 | K34: No significativo
A35: 34 | B35: P18649 | E35: 0.50598815 | F35: -1.5510262 | G35: 5.2681732 | H35: 0.0014464722 | I35: 0.0048073928 | J35: -1.6356581 | K35: No significativo
A36: 14 | B36: A0A8I3RP80 | C36: =VLOOKUP(B36,'Uniprot-API'!$A$1:$D$165,2,) -> NUCB1 | D36: =VLOOKUP(B36,'BiomaRt Ensembl'!$A$1:$F$327,2,) -> NUCB1 | E36: 1.0480861 | F36: -1.1868288 | G36: 11.031073 | H36: 1.8331573e-05 | I36: 0.00014517102 | J36: 3.2543296 | K36: Up en Corta
A37: 36 | B37: Q6EIY9 | E37: 0.96361856 | F37: -2.1821326 | G37: 5.0463779 | H37: 0.001823862 | I37: 0.0057249003 | J37: -1.8938365 | K37: No significativo
A38: 37 | B38: A0A8I3NMC7 | E38: 0.52607045 | F38: -3.9157345 | G38: 4.9383392 | H38: 0.0020468142 | I38: 0.0062375698 | J38: -2.0220993 | K38: No significativo
A39: 38 | B39: A0A8I3NYI8 | E39: 0.47687867 | F39: -1.8085675 | G39: 4.9155751 | H39: 0.0020975898 | I39: 0.0062375698 | J39: -2.0493361 | K39: No significativo
A40: 39 | B40: A0A8I3NTB5 | E40: 0.48593675 | F40: -3.0919516 | G40: 4.7346403 | H40: 0.0025551887 | I40: 0.0073986663 | J40: -2.2684596 | K40: No significativo
A41: 31 | B41: A0A8I3Q4E9 | C41: =VLOOKUP(B41,'Uniprot-API'!$A$1:$D$165,2,) -> TPM4 | D41: =VLOOKUP(B41,'BiomaRt Ensembl'!$A$1:$F$327,2,) -> RAB8A | E41: 1.1718618 | F41: -0.36128791 | G41: 5.543159 | H41: 0.0010948442 | I41: 0.0039908835 | J41: -1.3249428 | K41: Up en Corta
A42: 40 | B42: A0A8I3P0H1 | C42: =VLOOKUP(B42,'Uniprot-API'!$A$1:$D$165,2,) -> RRBP1 | D42: =VLOOKUP(B42,'BiomaRt Ensembl'!$A$1:$F$327,2,) -> RRBP1 | E42: 1.2426445 | F42: -3.5062636 | G42: 4.7123183 | H42: 0.0026189969 | I42: 0.0073986663 | J42: -2.2958195 | K42: Up en Corta
...

Sheet DEPs
A1: Accesion | B1: Uniprot-API | C1: Ensembl
A2: A0A8I3P6H2 | B2: =VLOOKUP(A2,'Uniprot-API'!$A$1:$D$165,2,) -> MPO | C2: |+! | L2: 1 | M2: Sexo+supervivencia
A3: A0A8I3PED8 | B3: =VLOOKUP(A3,'Uniprot-API'!$A$1:$D$165,2,) -> FN1 | C3: =VLOOKUP(A3,'BiomaRt Ensembl'!$A$1:$F$327,2,) -> FN1 | L3: 4 | M3: Sexo+edad
A4: P00011 | B4: =VLOOKUP(A4,'Uniprot-API'!$A$1:$D$165,2,) -> CYCS | C4: =VLOOKUP(A4,'BiomaRt Ensembl'!$A$1:$F$327,2,) -> CYCS | L4: 3 | M4: Edad+supervivencia
A5: A0A8I3PKH4 | B5: =VLOOKUP(A5,'Uniprot-API'!$A$1:$D$165,2,) -> PSMB1 | C5: =VLOOKUP(A5,'BiomaRt Ensembl'!$A$1:$F$327,2,) -> PSMB1 | L5: 2 | M5: Sexo+supervivencia+edad
A6: A0A8I3MJP4 | B6: =VLOOKUP(A6,'Uniprot-API'!$A$1:$D$165,2,) -> ALDOA | C6: =VLOOKUP(A6,'BiomaRt Ensembl'!$A$1:$F$327,2,) -> #N/A | L6: 18 | M6: Sexo
A7: A0A8I3NGP3 | B7: =VLOOKUP(A7,'Uniprot-API'!$A$1:$D$165,2,) -> C3 | C7: =VLOOKUP(A7,'BiomaRt Ensembl'!$A$1:$F$327,2,) -> #N/A | L7: 15 | M7: Supervivencia
A8: A0A8I3NU27 | B8: =VLOOKUP(A8,'Uniprot-API'!$A$1:$D$165,2,) -> 0 | C8: =VLOOKUP(A8,'BiomaRt Ensembl'!$A$1:$F$327,2,) -> #N/A | L8: 10 | M8: Edad
A9: A0A8I3MIR0 | B9: =VLOOKUP(A9,'Uniprot-API'!$A$1:$D$165,2,) -> SOD2 | C9: =VLOOKUP(A9,'BiomaRt Ensembl'!$A$1:$F$327,2,) -> SOD2 | L9: =SUM(L2:L8) -> 53 | M9: TOTAL
A10: E2R6K5 | B10: =VLOOKUP(A10,'Uniprot-API'!$A$1:$D$165,2,) -> GALK1 | C10: =VLOOKUP(A10,'BiomaRt Ensembl'!$A$1:$F$327,2,) -> H3-3A | L10: =SUM(L2:L5) -> 10 | M10: DUPLICADOS
A11: A0A8I3N371 | B11: =VLOOKUP(A11,'Uniprot-API'!$A$1:$D$165,2,) -> H2BC26 | C11: =VLOOKUP(A11,'BiomaRt Ensembl'!$A$1:$F$327,2,) -> #N/A
A12: A0A8I3NTB5 | B12: =VLOOKUP(A12,'Uniprot-API'!$A$1:$D$165,2,) -> CANT1 | C12: =VLOOKUP(A12,'BiomaRt Ensembl'!$A$1:$F$327,2,) -> #N/A
A13: A0A8I3MQ40 | B13: =VLOOKUP(A13,'Uniprot-API'!$A$1:$D$165,2,) -> SERPINA5 | C13: =VLOOKUP(A13,'BiomaRt Ensembl'!$A$1:$F$327,2,) -> SERPINA5
A14: A0A8I3P1P3 | B14: =VLOOKUP(A14,'Uniprot-API'!$A$1:$D$165,2,) -> SERPINB1 | C14: =VLOOKUP(A14,'BiomaRt Ensembl'!$A$1:$F$327,2,) -> SERPINB1
A15: A0A8I3N262 | B15: =VLOOKUP(A15,'Uniprot-API'!$A$1:$D$165,2,) -> DHODH | C15: =VLOOKUP(A15,'BiomaRt Ensembl'!$A$1:$F$327,2,) -> DHODH
A16: A0A8I3MEU8 | B16: =VLOOKUP(A16,'Uniprot-API'!$A$1:$D$165,2,) -> NPM1 | C16: =VLOOKUP(A16,'BiomaRt Ensembl'!$A$1:$F$327,2,) -> NPM1
A17: A0A8I3SC19 | B17: =VLOOKUP(A17,'Uniprot-API'!$A$1:$D$165,2,) -> PGAM1 | C17: =VLOOKUP(A17,'BiomaRt Ensembl'!$A$1:$F$327,2,) -> PGAM1
A18: P49822 | B18: =VLOOKUP(A18,'Uniprot-API'!$A$1:$D$165,2,) -> ALB | C18: =VLOOKUP(A18,'BiomaRt Ensembl'!$A$1:$F$327,2,) -> #N/A
A19: A0A8I3P6W9 | B19: =VLOOKUP(A19,'Uniprot-API'!$A$1:$D$165,2,) -> RRBP1 | C19: =VLOOKUP(A19,'BiomaRt Ensembl'!$A$1:$F$327,2,) -> RRBP1
A20: A0A8I3NP20 | B20: =VLOOKUP(A20,'Uniprot-API'!$A$1:$D$165,2,) -> DPYSL2 | C20: =VLOOKUP(A20,'BiomaRt Ensembl'!$A$1:$F$327,2,) -> DPYSL2
A21: A0A8I3N7B3 | B21: =VLOOKUP(A21,'Uniprot-API'!$A$1:$D$165,2,) -> VCL | C21: =VLOOKUP(A21,'BiomaRt Ensembl'!$A$1:$F$327,2,) -> VCL
A22: A0A8I3RXV3 | B22: =VLOOKUP(A22,'Uniprot-API'!$A$1:$D$165,2,) -> PSMB3 | C22: =VLOOKUP(A22,'BiomaRt Ensembl'!$A$1:$F$327,2,) -> PSMB3
... A54: Q29393 | B54: =VLOOKUP(A54,'Uniprot-API'!$A$1:$D$165,2,) -> DCN | C54: =VLOOKUP(A54,'BiomaRt Ensembl'!$A$1:$F$327,2,) -> DCN

Sheet Uniprot-API
A1: Accesion | B1: Gene | C1: Ensembl | D1: Descripcion
A2: A0A8I3RZV0 | C2: ENSCAFT00845030810.1 | D2: Ig-like domain-containing protein
A3: A0A8I3N4C3 | B3: CALD1 | C3: ENSCAFT00845017697.1
A4: A0A8I3MJP4 | B4: ALDOA | C4: ENSCAFT00845002945.1 | D4: Fructose-bisphosphate aldolase
A5: A0A8I3NU27 | C5: ENSCAFT00845031249.1 | D5: Ig-like domain-containing protein
A6: A0A5B8JID5
A7: A0A8I3NGP3 | B7: C3 | C7: ENSCAFT00845018110.1 | D7: Complement C3
A8: A0A8I3NVY9 | B8: NME2 | C8: ENSCAFT00845027098.1 | D8: Nucleoside diphosphate kinase
A9: A0A8I3P237 | B9: TALDO1 | C9: ENSCAFT00845032096.1 | D9: Transaldolase
A10: E2R6K5 | B10: GALK1 | C10: ENSCAFT00845015667.1 | D10: Histone H3
A11: A0A8I3PK78 | B11: KRT75 | C11: ENSCAFT00845044629.1
A12: A0A8I3MHV0 | B12: FUBP1 | C12: ENSCAFT00845005963.1 | D12: Far upstream element-binding protein 1
A13: A0A8I3MIR0 | B13: SOD2 | C13: ENSCAFT00845003091.1 | D13: Superoxide dismutase [Mn], mitochondrial
A14: A0A8I3P6H2 | B14: MPO | C14: ENSCAFT00845032781.1 | D14: Myeloperoxidase
A15: A0A8I3N5W6 | B15: NES | C15: ENSCAFT00845014933.1
A16: A0A8I3PED8 | B16: FN1 | C16: ENSCAFT00845039001.1 | D16: Fibronectin
A17: A0A8I3P1Z4 | B17: COL1A2 | C17: ENSCAFT00845030530.1
A18: A0A8I3NNP1 | C18: ENSCAFT00845022797.1 | D18: Ig-like domain-containing protein
A19: A0A8I3S0B7 | B19: SERPINF1 | C19: ENSCAFT00845024478.1
A20: A0A8I3MKL7 | B20: APOA4 | C20: ENSCAFT00845007736.1 | D20: Apolipoprotein A-IV
A21: A0A8I3PJI1 | B21: DPP7 | C21: ENSCAFT00845043936.1 | D21: Dipeptidyl peptidase 2
A22: A0A8I3NP66 | B22: PSMA4 | C22: ENSCAFT00845023448.1 | D22: Proteasome subunit alpha type
A23: A0A8I3P9E1 | B23: TUBA1C | C23: ENSCAFT00845036871.1 | D23: Tubulin alpha chain
A24: A0A8I3NY33 | B24: AHCY | C24: ENSCAFT00845028066.1 | D24: Adenosylhomocysteinase
A25: A0A8I3PS70 | B25: OGN | C25: ENSCAFT00845043990.1 | D25: Mimecan
A26: A0A8I3MJ33 | B26: HBQ1 | C26: ENSCAFT00845001517.1
A27: A0A8I3PRM7 | B27: TPI1 | C27: ENSCAFT00845047845.1 | D27: Triosephosphate isomerase
A28: A0A8I3PNX9 | B28: COQ10B | C28: ENSCAFT00845046446.1 | D28: 10 kDa heat shock protein, mitochondrial
A29: P33703 | B29: APOH | C29: ENSCAFT00000017923 | D29: Beta-2-glycoprotein 1
A30: A0A8I3NSK4 | B30: PABPC1L | C30: ENSCAFT00845025254.1
A31: A0A8I3NTB5 | B31: CANT1 | C31: ENSCAFT00845025603.1 | D31: Galectin-3-binding protein
A32: A0A8I3PCE5 | B32: PSMA2 | C32: ENSCAFT00845031871.1 | D32: Proteasome subunit alpha type
A33: A0A8I3S396 | B33: SOD1 | C33: ENSCAFT00845040105.1 | D33: Superoxide dismutase [Cu-Zn]
A34: A0A8I3PX06 | B34: KCTD12 | C34: ENSCAFT00845045957.1
A35: A0A8I3Q5N9 | B35: LOC119877479 | C35: ENSCAFT00845051100.1 | D35: Glyceraldehyde-3-phosphate dehydrogenase
A36: A0A8I3NYI8 | B36: FMOD | C36: ENSCAFT00845034027.1 | D36: Fibromodulin
A37: A0A8I3P9P7 | B37: MARCKS | C37: ENSCAFT00845036515.1 | D37: Myristoylated alanine-rich C-kinase substrate
A38: A0A8I3N8Y1 | B38: FGG | C38: ENSCAFT00845017343.1 | D38: Fibrinogen gamma chain
A39: A0A8I3P1L4 | B39: COL1A2 | C39: ENSCAFT00845030214.1
A40: A0A8I3N371 | B40: H2BC26 | C40: ENSCAFT00845012690.1 | D40: Histone H2B
...

Sheet BiomaRt Ensembl
A1: uniprot_gn_id | B1: external_gene_name | C1: ensembl_gene_id | D1: ensembl_transcript_id | E1: description | F1: gene_biotype
A2: A0A1K0GGH0 | B2: GLNA2 | C2: ENSCAFG00845020234 | D2: ENSCAFT00845035632 | F2: protein_coding
A3: A0A1K0GGH0 | B3: GLNA2 | C3: ENSCAFG00845020234 | D3: ENSCAFT00845035684 | F3: protein_coding
A4: A0A1K0GGH0 | B4: GLNA2 | C4: ENSCAFG00845020234 | D4: ENSCAFT00845035729 | F4: protein_coding
A5: A0A1K0GGH0 | B5: GLNA2 | C5: ENSCAFG00845020234 | D5: ENSCAFT00845035780 | F5: protein_coding
A6: A0A1K0GGH0 | B6: GLNA2 | C6: ENSCAFG00845020234 | D6: ENSCAFT00845035819 | F6: protein_coding
A7: A0A1K0GGH0 | B7: GLNA2 | C7: ENSCAFG00845020234 | D7: ENSCAFT00845035888 | F7: protein_coding
A8: A0A1K0GGH0 | B8: GLNA2 | C8: ENSCAFG00845020234 | D8: ENSCAFT00845035936 | F8: protein_coding
A9: A0A1K0GGH0 | B9: GLNA2 | C9: ENSCAFG00845020234 | D9: ENSCAFT00845035990 | F9: protein_coding
A10: A0A1K0GGH0 | B10: GLNA2 | C10: ENSCAFG00845020234 | D10: ENSCAFT00845036033 | F10: protein_coding
A11: A0A1K0GGH0 | B11: GLNA2 | C11: ENSCAFG00845020234 | D11: ENSCAFT00845036079 | F11: protein_coding
A12: A0A5B8JID5 | C12: ENSCAFG00845000903 | D12: ENSCAFT00845001517 | F12: protein_coding
A13: A0A5B8JID5 | C13: ENSCAFG00845000903 | D13: ENSCAFT00845001533 | F13: protein_coding
A14: A0A5B8JID5 | C14: ENSCAFG00845000903 | D14: ENSCAFT00845001547 | F14: protein_coding
A15: A0A5B8JID5 | C15: ENSCAFG00845000903 | D15: ENSCAFT00845001557 | F15: protein_coding
A16: A0A5B8JID5 | C16: ENSCAFG00845000903 | D16: ENSCAFT00845001577 | F16: protein_coding
A17: A0A5B8JID5 | C17: ENSCAFG00845000903 | D17: ENSCAFT00845001592 | F17: protein_coding
A18: A0A5F4CSK0 | B18: TPM3 | C18: ENSCAFG00845015257 | D18: ENSCAFT00845027226 | E18: tropomyosin 3 [Source:NCBI gene (formerly Entrezgene);Acc:480137] | F18: protein_coding
A19: A0A5F4CSK0 | B19: TPM3 | C19: ENSCAFG00845015257 | D19: ENSCAFT00845027235 | E19: tropomyosin 3 [Source:NCBI gene (formerly Entrezgene);Acc:480137] | F19: protein_coding
A20: A0A5F4CSK0 | B20: TPM3 | C20: ENSCAFG00845015257 | D20: ENSCAFT00845027269 | E20: tropomyosin 3 [Source:NCBI gene (formerly Entrezgene);Acc:480137] | F20: protein_coding
A21: A0A5F4CSK0 | B21: TPM3 | C21: ENSCAFG00845015257 | D21: ENSCAFT00845027289 | E21: tropomyosin 3 [Source:NCBI gene (formerly Entrezgene);Acc:480137] | F21: protein_coding
A22: A0A5F4CSK0 | B22: TPM3 | C22: ENSCAFG00845015257 | D22: ENSCAFT00845027340 | E22: tropomyosin 3 [Source:NCBI gene (formerly Entrezgene);Acc:480137] | F22: protein_coding
A23: A0A5F4CSK0 | B23: TPM3 | C23: ENSCAFG00845015257 | D23: ENSCAFT00845027403 | E23: tropomyosin 3 [Source:NCBI gene (formerly Entrezgene);Acc:480137] | F23: protein_coding
A24: A0A5F4CSK0 | B24: TPM3 | C24: ENSCAFG00845015257 | D24: ENSCAFT00845027442 | E24: tropomyosin 3 [Source:NCBI gene (formerly Entrezgene);Acc:480137] | F24: protein_coding
A25: A0A5F4CSK0 | B25: TPM3 | C25: ENSCAFG00845015257 | D25: ENSCAFT00845027475 | E25: tropomyosin 3 [Source:NCBI gene (formerly Entrezgene);Acc:480137] | F25: protein_coding
A26: A0A8I3M9P4 | B26: ANXA1 | C26: ENSCAFG00845000040 | D26: ENSCAFT00845000063 | E26: annexin A1 [Source:NCBI gene (formerly Entrezgene);Acc:476322] | F26: protein_coding
A27: A0A8I3MC47 | B27: ANPEP | C27: ENSCAFG00845000639 | D27: ENSCAFT00845001074 | E27: alanyl aminopeptidase, membrane [Source:NCBI gene (formerly Entrezgene);Acc:403913] | F27: protein_coding
A28: A0A8I3MC47 | B28: ANPEP | C28: ENSCAFG00845000639 | D28: ENSCAFT00845001107 | E28: alanyl aminopeptidase, membrane [Source:NCBI gene (formerly Entrezgene);Acc:403913] | F28: protein_coding
A29: A0A8I3MC47 | B29: ANPEP | C29: ENSCAFG00845000639 | D29: ENSCAFT00845001119 | E29: alanyl aminopeptidase, membrane [Source:NCBI gene (formerly Entrezgene);Acc:403913] | F29: protein_coding
... A36: A0A8I3MGB5 | B36: ALPL | C36: ENSCAFG00845001491 | D36: ENSCAFT00845002731 | E36: alkaline phosphatase, biomineralization associated [Source:NCBI gene (formerly Entrezgene);Acc:403548] | F36: protein_coding
A37: A0A8I3MGZ7 | B37: ITGB1 | C37: ENSCAFG00845002947 | D37: ENSCAFT00845005381 | F37: protein_coding
A38: A0A8I3MGZ7 | B38: ITGB1 | C38: ENSCAFG00845002947 | D38: ENSCAFT00845005404 | F38: protein_coding
A39: A0A8I3MGZ7 | B39: ITGB1 | C39: ENSCAFG00845002947 | D39: ENSCAFT00845005439 | F39: protein_coding
A40: A0A8I3MHV0 | B40: FUBP1 | C40: ENSCAFG00845003294 | D40: ENSCAFT00845005963 | E40: far upstream element binding protein 1 [Source:VGNC Symbol;Acc:VGNC:111504] | F40: protein_coding
A41: A0A8I3MHV0 | B41: FUBP1 | C41: ENSCAFG00845003294 | D41: ENSCAFT00845005975 | E41: far upstream element binding protein 1 [Source:VGNC Symbol;Acc:VGNC:111504] | F41: protein_coding
A42: A0A8I3MHV0 | B42: FUBP1 | C42: ENSCAFG00845003294 | D42: ENSCAFT00845006004 | E42: far upstream element binding protein 1 [Source:VGNC Symbol;Acc:VGNC:111504] | F42: protein_coding
A43: A0A8I3MHV0 | B43: FUBP1 | C43: ENSCAFG00845003294 | D43: ENSCAFT00845006018 | E43: far upstream element binding protein 1 [Source:VGNC Symbol;Acc:VGNC:111504] | F43: protein_coding
A44: A0A8I3MHV0 | B44: FUBP1 | C44: ENSCAFG00845003294 | D44: ENSCAFT00845006049 | E44: far upstream element binding protein 1 [Source:VGNC Symbol;Acc:VGNC:111504] | F44: protein_coding
A45: A0A8I3MIR0 | B45: SOD2 | C45: ENSCAFG00845001754 | D45: ENSCAFT00845003067 | E45: superoxide dismutase 2 [Source:HGNC Symbol;Acc:HGNC:11180] | F45: protein_coding
A46: A0A8I3MIR0 | B46: SOD2 | C46: ENSCAFG00845001754 | D46: ENSCAFT00845003078 | E46: superoxide dismutase 2 [Source:HGNC Symbol;Acc:HGNC:11180] | F46: protein_coding
...
